Workbook
Name ExternalData_1: '5Y Fin. Summary'!$A$3:$E$14
Name ExternalData_1: SOFP!$A$2:$A$60
Name ExternalData_6: CF!$A$2:$G$99

Sheet 5Y Fin. Summary
A1: Financial Summary - Ceylon Beverage Holdings
B2: 2020 | C2: 2021 | D2: 2022 | E2: 2023 | F2: 2024 | G2: 2025 | H2: 2026 | I2: 2027 | J2: 2028 | K2: 2029 | L2: 2030
A3: OPERATING RESULTS
A4: Revenue | B4: =IS!C3 -> 49215361 | C4: =IS!D3 -> 51172154 | D4: =IS!E3 -> 60211220 | E4: =IS!F3 -> 96938522 | F4: =IS!G3 -> 111930270 | G4: =IS!H3 -> 125172015 | H4: =IS!I3 -> 1.4036001e+08 | I4: =IS!J3 -> 1.5739567e+08 | ... L4: =IS!M3 -> 2.21985e+08
A5: Other income | B5: =IS!$C5 -> 11012389 | C5: =IS!$D5 -> 10506410 | D5: =IS!$E5 -> 12377783 | E5: =IS!$F5 -> 23182851 | F5: 530383 | G5: =IS!$B5 -> 11263256 | H5: =IS!I6 -> 421080.04 | I5: =IS!J6 -> 472187.02 | J5: =IS!K6 -> 529513.45 | K5: =IS!L6 -> 593818.65 | L5: =IS!M6 -> 665955.01
A6: Net gains arising from changes in fair value of investment properties | B6: 155609 | C6: - | D6: 160230 | E6: 163100 | F6: 5000 | G6: 350172 | H6: =IS!I7 -> 75677 | I6: =IS!J7 -> 75677 | J6: =IS!K7 -> 75677 | K6: =IS!L7 -> 75677 | L6: =IS!M7 -> 75677
B7: 49524307 | C7: 51,516,023 | D7: 60565372 | E7: 97406036 | F7: 112465653 | G7: =SUM(G4+G5+G6) -> 136785443 | H7: =SUM(H4+H5+H6) -> 1.4085677e+08 | I7: =SUM(I4+I5+I6) -> 1.5794354e+08 | J7: =SUM(J4+J5+J6) -> 1.7710967e+08 | K7: =SUM(K4+K5+K6) -> 1.9860905e+08 | L7: =SUM(L4+L5+L6) -> 2.2272664e+08
A8: Total expenditure | B8: -43550492 | C8: (46,194,221) | D8: -54389494 | E8: -83587984 | F8: -97099425 | G8: =G10-G7 -> -120186589 | H8: =H10-H7 -> -1.2153583e+08 | I8: =I10-I7 -> -1.3615532e+08 | J8: =J10-J7 -> -1.5269708e+08 | K8: =K10-K7 -> -1.7138539e+08 | L8: =L10-L7 -> -1.9234168e+08
A9: Reversal / (provision) impairment of intangible assets | B9: -740315 | C9: (449,084) | D9: -463578 | E9: -353229 | F9: 291063 | G9: - | H9: =IS!I12 -> 0 | I9: =IS!J12 -> 0 | J9: =IS!K12 -> 0 | K9: =IS!L12 -> 0 | L9: =IS!M12 -> 0
A10: EBIT | B10: 5233500 | C10: 4,872,718 | D10: 5712300 | E10: 13464823 | F10: 15657291 | G10: 16598854 | H10: =IS!I15 -> 19320940 | I10: =IS!J15 -> 21788217 | J10: =IS!K15 -> 24412591 | K10: =IS!L15 -> 27223652 | L10: =IS!M15 -> 30384955
A11: Net finance income/(costs) | B11: -739260 | C11: (588,211) | D11: 172876 | E11: -2203920 | F11: -1633998 | G11: -562630 | H11: =IS!I17 -> -1077448.6 | I11: =IS!J17 -> -883951.22 | J11: =IS!K17 -> -647652.2 | K11: =IS!L17 -> -359083.84 | L11: =IS!M17 -> -6684.1523
A12: EBT | B12: 4494240 | C12: 4,284,507 | D12: 5885176 | E12: 11260903 | F12: 14023293 | G12: 16036224 | H12: =IS!I19 -> 19368016 | I12: =IS!J19 -> 22165276 | J12: =IS!K19 -> 25179043 | K12: =IS!L19 -> 28450405 | L12: =IS!M19 -> 32156752
A13: Income tax expense | B13: -1677977 | C13: (1,850,010) | D13: -2063378 | E13: -4514799 | F13: -6047684 | G13: -6378562 | H13: =IS!I20 -> -7940540.7 | I13: =IS!J20 -> -9154271 | J13: =IS!K20 -> -10245708 | K13: =IS!L20 -> -11663687 | L13: =IS!M20 -> -13182985
A14: Net Income | B14: 2816263 | C14: 2,434,497 | D14: 3821798 | E14: 6746104 | F14: 7975609 | G14: 9657662 | H14: =IS!I21 -> 11427476 | I14: =IS!J21 -> 13011005 | J14: =IS!K21 -> 14933336 | K14: =IS!L21 -> 16786718 | L14: =IS!M21 -> 18973768

Sheet Assumptions
A1: Assumptions Sheet | B1: 2019 | C1: 2020 | D1: 2021 | E1: 2022 | F1: 2023 | G1: 2024 | H1: 2025 | I1: 2026 | J1: 2027 | K1: 2028 | L1: 2029 | M1: 2030
A3: Revenue Assumptions
A4: Revenue Growth Rates
A5: Domestic Revenue | C5: =IS!C36/IS!B36-1 -> 0.11677425 | D5: =IS!D36/IS!C36-1 -> 0.042923152 | E5: =IS!E36/IS!D36-1 -> 0.17535269 | F5: =IS!F36/IS!E36-1 -> 0.59634201 | G5: =IS!G36/IS!F36-1 -> 0.15453027 | H5: =IS!H36/IS!G36-1 -> 0.11734451 | I5: 0.12 | J5: =I5 -> 0.12 | K5: =J5 -> 0.12 | L5: =K5 -> 0.12 | M5: =L5 -> 0.12
A6: Export revenue | C6: =IS!C37/IS!B37-1 -> 0.024864954 | D6: =IS!D37/IS!C37-1 -> -0.041769119 | E6: =IS!E37/IS!D37-1 -> 0.21275971 | F6: =IS!F37/IS!E37-1 -> 0.98057985 | G6: =IS!G37/IS!F37-1 -> 0.15732203 | H6: =IS!H37/IS!G37-1 -> 0.13926632 | I6: 0.15 | J6: =I6 -> 0.15 | K6: =J6 -> 0.15 | L6: =K6 -> 0.15 | M6: =L6 -> 0.15
A8: Other Income
A9: As a % of revenue | B9: =IS!B6/IS!B3 -> 0.0031215492 | C9: =IS!C6/IS!C3 -> 0.0031156329 | D9: =IS!D6/IS!D3 -> 0.0067198461 | E9: =IS!E6/IS!E3 -> 0.0032206954 | F9: =IS!F6/IS!F3 -> 0.0031402789 | G9: =IS!G6/IS!G3 -> 0.0047385126 | H9: =IS!H6/IS!H3 -> 0.0027975263 | I9: 0.003 | J9: =I9 -> 0.003 | K9: =J9 -> 0.003 | L9: =K9 -> 0.003 | M9: =L9 -> 0.003
A12: Cost Assumptions
A13: Cost of Sales
A14: As a % of revenue | B14: =ABS(IS!B4/IS!B3) -> 0.74527218 | C14: =ABS(IS!C4/IS!C3) -> 0.77624082 | D14: =ABS(IS!D4/IS!D3) -> 0.79468502 | E14: =ABS(IS!E4/IS!E3) -> 0.7944273 | F14: =ABS(IS!F4/IS!F3) -> 0.76084996 | G14: =ABS(IS!G4/IS!G3) -> 0.75818146 | H14: =ABS(IS!H4/IS!H3) -> 0.76371535 | I14: =ABS(AVERAGE(F14:H14)) -> 0.76091559 | J14: =I14 -> 0.76091559 | K14: =J14 -> 0.76091559 | L14: =K14 -> 0.76091559 | M14: =L14 -> 0.76091559
A16: Distribution expenses
A17: As a % of revenue | B17: =ABS(IS!B9/IS!B3) -> 0.068543385 | C17: =ABS(IS!C9/IS!C3) -> 0.061399265 | D17: =ABS(IS!D9/IS!D3) -> 0.056819007 | E17: =ABS(IS!E9/IS!E3) -> 0.058350204 | F17: =ABS(IS!F9/IS!F3) -> 0.062073352 | G17: =ABS(IS!G9/IS!G3) -> 0.067127838 | H17: =ABS(IS!H9/IS!H3) -> 0.064565894 | I17: =AVERAGE(B17:H17) -> 0.062696992 | J17: =AVERAGE(C17:I17) -> 0.061861793 | K17: =AVERAGE(D17:J17) -> 0.061927869 | L17: =AVERAGE(E17:K17) -> 0.062657706 | M17: =AVERAGE(F17:L17) -> 0.063273063
A19: Administrative expenses
A20: As a % of revenue | B20: =ABS(IS!B10/IS!B3) -> 0.037471685 | C20: =ABS(IS!C10/IS!C3) -> 0.036180716 | D20: =ABS(IS!D10/IS!D3) -> 0.03710731 | E20: =ABS(IS!E10/IS!E3) -> 0.03930221 | F20: =ABS(IS!F10/IS!F3) -> 0.031977886 | G20: =ABS(IS!G10/IS!G3) -> 0.037163325 | H20: =ABS(IS!H10/IS!H3) -> 0.037051349 | I20: =H20 -> 0.037051349 | J20: =I20 -> 0.037051349 | K20: =J20 -> 0.037051349 | L20: =K20 -> 0.037051349 | M20: =L20 -> 0.037051349
A22: Other expenses
A23: As a % of revenue | B23: =ABS(IS!B11/IS!B3) -> 0.0093440898 | C23: =ABS(IS!C11/IS!C3) -> 0.011075526 | D23: =ABS(IS!D11/IS!D3) -> 0.014110506 | E23: =ABS(IS!E11/IS!E3) -> 0.011231893 | F23: =ABS(IS!F11/IS!F3) -> 0.0073770982 | G23: =ABS(IS!G11/IS!G3) -> 0.0050266206 | H23: =ABS(IS!H11/IS!H3) -> 0.0052224932 | I23: =H23 -> 0.0052224932 | J23: =I23 -> 0.0052224932 | K23: =J23 -> 0.0052224932 | L23: =K23 -> 0.0052224932 | M23: =L23 -> 0.0052224932
A25: Finance income
A26: As a % of revenue | B26: =IS!B16/IS!B3 -> 0.022840241 | C26: =IS!C16/IS!C3 -> 0.019321305 | D26: =IS!D16/IS!D3 -> 0.012979579 | E26: =IS!E16/IS!E3 -> 0.01042324 | F26: =IS!F16/IS!F3 -> 0.014560992 | G26: =IS!G16/IS!G3 -> 0.010293266 | H26: =IS!H16/IS!H3 -> 0.0080117189 | I26: =H26 -> 0.0080117189 | J26: =I26 -> 0.0080117189 | K26: =J26 -> 0.0080117189 | L26: =K26 -> 0.0080117189 | M26: =L26 -> 0.0080117189
A29: Effective Tax Rate | B29: =ABS(IS!B20/IS!B19) -> 0.41232024 | C29: =ABS(IS!C20/IS!C19) -> 0.37336168 | D29: =ABS(IS!D20/IS!D19) -> 0.43179064 | E29: =ABS(IS!E20/IS!E19) -> 0.350606 | F29: =ABS(IS!F20/IS!F19) -> 0.40092691 | G29: =ABS(IS!G20/IS!G19) -> 0.4312599 | H29: =ABS(IS!H20/IS!H19) -> 0.3977596 | I29: =AVERAGE(F29:H29) -> 0.40998214 | J29: =AVERAGE(G29:I29) -> 0.41300055 | K29: =AVERAGE(H29:J29) -> 0.40691409 | L29: =AVERAGE(I29:K29) -> 0.40996559 | M29: =AVERAGE(J29:L29) -> 0.40996008
A31: Depreciation Rate | B31: =CF!B8/SOFP!B5 -> 0.067415487 | C31: =CF!C8/SOFP!C5 -> 0.064160855 | D31: =CF!D8/SOFP!D5 -> 0.069907165 | E31: =CF!E8/SOFP!E5 -> 0.074509277 | F31: =CF!F8/SOFP!F5 -> 0.078128969 | G31: =CF!G8/SOFP!G5 -> 0.086868488 | H31: =CF!H8/SOFP!H5 -> 0.09514721 | I31: =H31 -> 0.09514721 | J31: =I31 -> 0.09514721 | K31: =J31 -> 0.09514721 | L31: =K31 -> 0.09514721 | M31: =L31 -> 0.09514721
A32: Ammortization Rate (5years -> 20% ) | B32: 0.2 | C32: 0.2 | D32: 0.2 | E32: 0.2 | F32: 0.2 | G32: 0.2 | H32: 0.2 | I32: 0.2 | J32: 0.2 | K32: 0.2 | L32: 0.2 | M32: 0.2
A33: Lease Rate (20%) | C33: =CF!C6/SOFP!C9 -> 0.22709008 | D33: =CF!D6/SOFP!D9 -> 0.32529093 | E33: =CF!E6/SOFP!E9 -> 0.33845842 | F33: =CF!F6/SOFP!F9 -> 0.31325049 | G33: =CF!G6/SOFP!G9 -> 0.28359282 | H33: =CF!H6/SOFP!H9 -> 0.074148719 | I33: =AVERAGE(F33:H33) -> 0.22366401 | J33: =I33 -> 0.22366401 | K33: =J33 -> 0.22366401 | L33: =K33 -> 0.22366401 | M33: =L33 -> 0.22366401
A35: PPE Addition (As a % of GDP) | I35: 0.025 | J35: 0.025 | K35: 0.025 | L35: 0.025 | M35: 0.025
A36: Intangible Additions (As a % to Revenue) | B36: =CapEx!B13/IS!B3 -> 0.0011128116 | C36: =CapEx!C13/IS!C3 -> 0.00011675217 | D36: =CapEx!D13/IS!D3 -> 0.00053146092 | E36: =CapEx!E13/IS!E3 -> 0.00012384735 | F36: =CapEx!F13/IS!F3 -> 8.0618106e-05 | G36: =CapEx!G13/IS!G3 -> 0.00036828286 | H36: =CapEx!H13/IS!H3 -> 0.00020887257 | I36: 0.0005 | J36: =I36 -> 0.0005 | K36: =J36 -> 0.0005 | L36: =K36 -> 0.0005 | M36: =L36 -> 0.0005
A37: ROU Addition (Lease to revenue) | B37: =CapEx!B21/IS!B3 -> 0 | C37: =CapEx!C21/IS!C3 -> 0.0047797882 | D37: =CapEx!D21/IS!D3 -> 0.00097293149 | E37: =CapEx!E21/IS!E3 -> 0.00067856124 | F37: =CapEx!F21/IS!F3 -> 0.00078447658 | G37: =CapEx!G21/IS!G3 -> 0.00082131491 | H37: =CapEx!H21/IS!H3 -> 0.00047905277 | I37: =H37 -> 0.00047905277 | J37: =I37 -> 0.00047905277 | K37: =J37 -> 0.00047905277 | L37: =K37 -> 0.00047905277 | M37: =L37 -> 0.00047905277

Sheet IS
A1: STATEMENT OF PROFIT OR LOSS
A2: For the year ended 31st March (In Rs.’000s) | B2: 2019 | C2: 2020 | D2: 2021 | E2: 2022 | F2: 2023 | G2: 2024 | H2: 2025 | I2: 2026 | J2: 2027 | K2: 2028 | L2: 2029 | M2: 2030
A3: Revenue | B3: 44216827 | C3: 49215361 | D3: 51172154 | E3: 60211220 | F3: 96938522 | G3: 111930270 | H3: 125172015 | I3: =I38 -> 1.4036001e+08 | J3: =J38 -> 1.5739567e+08 | K3: =K38 -> 1.7650448e+08 | L3: =L38 -> 1.9793955e+08 | M3: =M38 -> 2.21985e+08
A4: Cost of sales | B4: -32953571 | C4: -38202972 | D4: -40665744 | E4: -47833437 | F4: -73755671 | G4: -84863456 | H4: -95595789 | I4: =-I3*(Assumptions!I14) -> -1.0680212e+08 | J4: =-J3*(Assumptions!J14) -> -1.1976482e+08 | K4: =-K3*(Assumptions!K14) -> -1.3430501e+08 | L4: =-L3*(Assumptions!L14) -> -1.5061529e+08 | M4: =-M3*(Assumptions!M14) -> -1.6891185e+08
A5: Gross profit | B5: 11263256 | C5: 11012389 | D5: 10506410 | E5: 12377783 | F5: 23182851 | G5: 27066814 | H5: 29576226 | I5: =I3+I4 -> 33557891 | J5: =J3+J4 -> 37630852 | K5: =K3+K4 -> 42199470 | L5: =L3+L4 -> 47324260 | M5: =M3+M4 -> 53073153
A6: Other income | B6: 138025 | C6: 153337 | D6: 343869 | E6: 193922 | F6: 304414 | G6: 530383 | H6: 350172 | I6: =I3*Assumptions!I9 -> 421080.04 | J6: =J3*Assumptions!J9 -> 472187.02 | K6: =K3*Assumptions!K9 -> 529513.45 | L6: =L3*Assumptions!L9 -> 593818.65 | M6: =M3*Assumptions!M9 -> 665955.01
A7: Net gains arising from changes in fair value of investment properties | B7: 0 | C7: 155609 | D7: 0 | E7: 160230 | F7: 163100 | G7: 5000 | H7: 45800 | I7: =AVERAGE(B7:H7) -> 75677 | J7: =I7 -> 75677 | K7: =J7 -> 75677 | L7: =K7 -> 75677 | M7: =L7 -> 75677
B8: =SUM(B5:B7) -> 11401281 | C8: =SUM(C5:C7) -> 11321335 | D8: =SUM(D5:D7) -> 10850279 | E8: =SUM(E5:E7) -> 12731935 | F8: =SUM(F5:F7) -> 23650365 | G8: =SUM(G5:G7) -> 27602197 | H8: =SUM(H5:H7) -> 29972198 | I8: =SUM(I5:I7) -> 34054648 | ... M8: =SUM(M5:M7) -> 53814785
A9: Distribution expenses | B9: -3030771 | C9: -3021787 | D9: -2907551 | E9: -3513337 | F9: -6017299 | G9: -7513637 | H9: -8081843 | I9: =-I3*Assumptions!I17 -> -8800150.7 | J9: =-J3*Assumptions!J17 -> -9736778.7 | K9: =-K3*Assumptions!K17 -> -10930547 | L9: =-L3*Assumptions!L17 -> -12402438 | M9: =-M3*Assumptions!M17 -> -14045671
A10: Administrative expenses | B10: -1656879 | C10: -1780647 | D10: -1898861 | E10: -2366434 | F10: -3099889 | G10: -4159701 | H10: -4637792 | I10: =-(I3*Assumptions!I20) -> -5200527.8 | J10: =-(J3*Assumptions!J20) -> -5831722 | K10: =-(K3*Assumptions!K20) -> -6539729.2 | L10: =-(L3*Assumptions!L20) -> -7333927.3 | M10: =-(M3*Assumptions!M20) -> -8224843.8
A11: Other expenses | B11: -413166 | C11: -545086 | D11: -722065 | E11: -676286 | F11: -715125 | G11: -562631 | H11: -653710 | I11: =-I3*Assumptions!I23 -> -733029.22 | J11: =-J3*Assumptions!J23 -> -821997.84 | K11: =-K3*Assumptions!K23 -> -921793.47 | L11: =-L3*Assumptions!L23 -> -1033738 | M11: =-M3*Assumptions!M23 -> -1159315.2
A12: Reversal / (provision) - impairment of intercompany receivable | D12: 0 | E12: 0 | F12: 0 | G12: 0 | H12: 0 | I12: 0 | J12: 0 | K12: 0 | L12: 0 | M12: 0
A13: Impairment of investments in subsidiaries | B13: 0 | C13: 0 | D13: 0 | E13: 0 | F13: 0 | G13: 0 | H13: 0 | I13: 0 | J13: 0 | K13: 0 | L13: 0 | M13: 0
A14: Reversal / (provision) - impairment of intangible assets | B14: - | C14: -740315 | E14: -463578 | F14: -353229 | G14: 291063 | H14: -
A15: Operating Income (EBIT) | B15: =SUM(B8:B14) -> 6300465 | C15: =SUM(C8:C14) -> 5233500 | D15: =SUM(D8:D14) -> 5321802 | E15: 5712300 | F15: =SUM(F8:F14) -> 13464823 | G15: =SUM(G8:G14) -> 15657291 | H15: 16598854 | I15: =SUM(I8:I14) -> 19320940 | J15: =SUM(J8:J14) -> 21788217 | K15: =SUM(K8:K14) -> 24412591 | L15: =SUM(L8:L14) -> 27223652 | M15: =SUM(M8:M14) -> 30384955
A16: Finance income | B16: 1009923 | C16: 950905 | D16: 664193 | E16: 627596 | F16: 1411521 | G16: 1152128 | H16: 1002843 | I16: =I3*Assumptions!I26 -> 1124525 | J16: =J3*Assumptions!J26 -> 1261009.9 | K16: =K3*Assumptions!K26 -> 1414104.3 | L16: =L3*Assumptions!L26 -> 1585836 | M16: =M3*Assumptions!M26 -> 1778481.5
A17: Finance costs | B17: -2094515 | C17: -1690165 | D17: -1252404 | E17: -454720 | F17: -3615441 | G17: -2786126 | H17: -1565473 | I17: =-'Loan Schedule'!B5 -> -1077448.6 | J17: =-'Loan Schedule'!C5 -> -883951.22 | K17: =-'Loan Schedule'!D5 -> -647652.2 | L17: =-'Loan Schedule'!E5 -> -359083.84 | M17: =-'Loan Schedule'!F5 -> -6684.1523
A18: Net finance income / (costs) | B18: -1084592 | C18: -739260 | D18: -588211 | E18: 172876 | F18: -2203920 | G18: -1633998 | H18: -562630 | I18: =I16+I17 -> 47076.362 | J18: =J16+J17 -> 377058.69 | K18: =K16+K17 -> 766452.12 | L18: =L16+L17 -> 1226752.2 | M18: =M16+M17 -> 1771797.3
A19: Income before Tax (EBT) | B19: 5215873 | C19: 4494240 | D19: 4284507 | E19: 5885176 | F19: 11260903 | G19: 14023293 | H19: 16036224 | I19: =I15+I18 -> 19368016 | J19: =J15+J18 -> 22165276 | K19: =K15+K18 -> 25179043 | L19: =L15+L18 -> 28450405 | M19: =M15+M18 -> 32156752
A20: Less: Income tax expenses | B20: -2150610 | C20: -1677977 | D20: -1850010 | E20: -2063378 | F20: -4514799 | G20: -6047684 | H20: -6378562 | I20: =-I19*Assumptions!I29 -> -7940540.7 | J20: =-J19*Assumptions!J29 -> -9154271 | K20: =-K19*Assumptions!K29 -> -10245708 | L20: =-L19*Assumptions!L29 -> -11663687 | M20: =-M19*Assumptions!M29 -> -13182985
A21: Net Income | B21: 3065263 | C21: 2816263 | D21: 2434497 | E21: 3821798 | F21: 6746104 | G21: 7975609 | H21: 9657662 | I21: =I19+I20 -> 11427476 | J21: =J19+J20 -> 13011005 | K21: =K19+K20 -> 14933336 | L21: =L19+L20 -> 16786718 | M21: =M19+M20 -> 18973768
A24: Profit/(loss) attributable to
A25: - Equity holders of the company | B25: 1527293 | C25: 1473471 | D25: 1254900 | E25: 2452270 | F25: 3407614 | G25: 3962948 | H25: 4958100 | I25: =I21*0.5 -> 5713737.8 | J25: =J21*0.5 -> 6505502.4 | K25: =K21*0.5 -> 7466667.9 | L25: =L21*0.5 -> 8393358.8 | M25: =M21*0.5 -> 9486883.8
A26: - Non controlling interest | B26: 1537970 | C26: 1342792 | D26: 1180269 | E26: 2100614 | F26: 3338490 | G26: 4012661 | H26: 4394730 | I26: =I21*0.5 -> 5713737.8 | J26: =J21*0.5 -> 6505502.4 | K26: =K21*0.5 -> 7466667.9 | L26: =L21*0.5 -> 8393358.8 | M26: =M21*0.5 -> 9486883.8
A27: Profit available for appropriation | B27: 3065263 | C27: 2816263 | D27: 2434497 | E27: 3821798 | F27: 6746104 | G27: 7975609 | H27: =H25+H26 -> 9352830 | I27: =I25+I26 -> 11427476 | J27: =J25+J26 -> 13011005 | K27: =K25+K26 -> 14933336 | L27: =L25+L26 -> 16786718 | M27: =M25+M26 -> 18973768
A29: Earnings per Ordinary Share (Rs.) | B29: 72.77 | C29: 70.21 | D29: 59.77 | E29: 98.64 | F29: 162.36 | G29: 188.82 | H29: 243.82 | I29: =I25/DCF!$C$21 -> 272.23715 | J29: =J25/DCF!$C$21 -> 309.96162 | K29: =K25/DCF!$C$21 -> 355.75738 | L29: =L25/DCF!$C$21 -> 399.91056 | M29: =M25/DCF!$C$21 -> 452.01273
B31: =B25/B21 -> 0.49825839 | C31: =C25/C21 -> 0.52320078 | D31: =D25/D21 -> 0.51546582 | E31: =E25/E21 -> 0.64165348
A34: Revenue Breakdown
A35: Net Revenue by Geographical Split
A36: Domestic Revenue | B36: 42423178 | C36: 47377113 | D36: 49410688 | E36: 58074985 | F36: 92707538 | G36: 107033659 | H36: 119593471 | I36: =H36*(1+Assumptions!I5) -> 1.3394469e+08 | J36: =I36*(1+Assumptions!J5) -> 1.5001805e+08 | K36: =J36*(1+Assumptions!K5) -> 1.6802022e+08 | L36: =K36*(1+Assumptions!L5) -> 1.8818264e+08 | M36: =L36*(1+Assumptions!M5) -> 2.1076456e+08
A37: Export Revenue | B37: 1793649 | C37: 1838248 | D37: 1761466 | E37: 2136235 | F37: 4230984 | G37: 4896611 | H37: 5578544 | I37: =H37*(1+Assumptions!I6) -> 6415325.6 | J37: =I37*(1+Assumptions!J6) -> 7377624.4 | K37: =J37*(1+Assumptions!K6) -> 8484268.1 | L37: =K37*(1+Assumptions!L6) -> 9756908.3 | M37: =L37*(1+Assumptions!M6) -> 11220445
A38: Total Revenue | B38: =SUM(B36:B37) -> 44216827 | C38: =SUM(C36:C37) -> 49215361 | D38: =SUM(D36:D37) -> 51172154 | E38: =SUM(E36:E37) -> 60211220 | F38: =SUM(F36:F37) -> 96938522 | G38: =SUM(G36:G37) -> 111930270 | H38: =SUM(H36:H37) -> 125172015 | I38: =SUM(I36:I37) -> 1.4036001e+08 | ... M38: =SUM(M36:M37) -> 2.21985e+08

Sheet SOFP
